File: Shirley_example.vms
VAMAS Surface Chemical Analysis Standard Data Transfer Format 1988 May 4
Not Specified
Not Specified
Not Specified
Not Specified
5
Casa Info Follows CasaXPS Version 2.3.24rev1.1H
0
Created by SpecsLab Prodigy, Version 4.41.1-r70508
SourceAnalyserAngle: Not Specified
CasaRowLabel:Test-peak
NORM
REGULAR
1
1
Exp Variable
d
0
0
0
0
1
Test-peak
Test-peak
2018
2
3
0
55
31
0
20
Casa Info Follows
0
0
1
CASA region (*Mn 2p*) (*Shirley*) 838.0025 852.9175 13.91 2 0 0 0 -1643 0 0 (*Mn 2p*) 54.938 0 13.91
0


File = C:/Users/Public/Documents/SpecsLab Prodigy/Experiments/Experiment 2018-02-02_MnO in H2.sle
Group = Heating 100 C in vacuum
First of group = 0
Analyzer lens = SmallArea:3.5kV
Analyzer slit = 4:7x20c\C:mesh
Scan mode = FixedAnalyzerTransmission
Kinetic energy start = 798.71
Kinetic energy base = 0
PCA Coefs = 38186.9, -240.926, 1267.03, -362.764, -6.96917,
PCA Coefs = 38186.1, 244.237, 1340.87, 66.9934,
PCA Coefs = 38186.1, 244.237, 1340.87, 66.9934,
C:\Users\Mark\ownCloud\Muelheim Group\Projects\MnOx references\Experiment 2018-02-02_MnO in H2 - removed bad spectra.vms
XPS
1e+037
Al
1486.61
0
0
0
54.5
180
FAT
20
1
3.808
0
0
0
0
0
Test-peak

-1
Kinetic Energy
eV
837.61
0.1
2
Intensity
d
Intensity
d
pulse counting
0.4
2
0
0
0
0
3
PROPAGATION_CONVERGED
d
1
ESCAPE DEPTH TYPE
d
1
MFP Exponent
d
0
316
0
1
0
1
1285.48
2.12829
1285.71
2.12817
1285.99
2.12804
1286.31
2.12791
1286.6
2.12778
1286.93
2.12766
1287.41
2.12753
1287.82
2.1274
1288.25
2.12727
1288.56
2.12715
1288.88
2.12702
1289.27
2.12689
1289.66
2.12676
1290.12
2.12664
1290.4
2.12651
1290.87
2.12638
1291.38
2.12625
1291.84
2.12613
1292.42
2.126
1293.25
2.12587
1293.97
2.12575
1294.61
2.12562
1295.23
2.12549
1296.17
2.12536
1297.35
2.12524
1298.43
2.12511
1299.89
2.12498
1301.62
2.12486
1303.8
2.12473
1306.1
2.1246
1308.94
2.12448
1312.48
2.12435
1316.53
2.12422
1321.34
2.12409
1326.97
2.12397
1333.57
2.12384
1341.28
2.12371
1350.37
2.12359
1361.06
2.12346
1373.48
2.12333
1388.08
2.12321
1405.05
2.12308
1424.63
2.12295
1447.31
2.12283
1473.52
2.1227
1503.65
2.12257
1537.95
2.12245
1576.88
2.12232
1620.98
2.12219
1670.31
2.12207
1725.79
2.12194
1787.23
2.12181
1855.35
2.12169
1929.66
2.12156
2010.77
2.12144
2098.3
2.12131
2192.11
2.12118
2291.75
2.12106
2396.55
2.12093
2505.79
2.1208
2618.5
2.12068
2733.86
2.12055
2850.31
2.12042
2966.46
2.1203
3080.87
2.12017
3191.95
2.12005
3297.84
2.11992
3396.48
2.11979
3486.21
2.11967
3565.61
2.11954
3632.64
2.11942
3686.77
2.11929
3725.89
2.11916
3749.44
2.11904
3756.11
2.11891
3746.27
2.11879
3719.02
2.11866
3674.65
2.11853
3613.14
2.11841
3534.89
2.11828
3441.51
2.11816
3333.88
2.11803
3214.54
2.1179
3085.2
2.11778
2948.71
2.11765
2806.58
2.11753
2661.09
2.1174
2513.7
2.11728
2366.11
2.11715
2219.7
2.11703
2075.7
2.1169
1934.97
2.11677
1799.18
2.11665
1669.39
2.11652
1546.72
2.1164
1431.67
2.11627
1324.91
2.11615
1226.44
2.11602
1136.11
2.1159
1053.82
2.11577
979.059
2.11564
911.782
2.11552
851.113
2.11539
797.104
2.11527
748.779
2.11514
705.873
2.11502
668.01
2.11489
634.704
2.11477
605.344
2.11464
579.622
2.11452
557.255
2.11439
537.651
2.11427
520.754
2.11414
505.887
2.11402
492.961
2.11389
481.76
2.11377
472.024
2.11364
463.461
2.11352
455.996
2.11339
449.455
2.11327
443.736
2.11314
438.769
2.11302
434.24
2.11289
430.269
2.11277
426.751
2.11264
423.632
2.11252
420.82
2.11239
418.358
2.11227
416.094
2.11214
414.084
2.11202
412.3
2.11189
410.751
2.11177
409.278
2.11164
407.926
2.11152
406.567
2.1114
405.342
2.11127
404.302
2.11115
403.361
2.11102
402.499
2.1109
401.592
2.11077
400.768
2.11065
400.008
2.11052
399.231
2.1104
398.631
2.11027
398.097
2.11015
397.598
2.11003
397.023
2.1099
396.495
2.10978
395.975
2.10965
395.537
2.10953
395.101
2.1094
394.7
2.10928
394.26
2.10916
393.882
2.10903
393.49
2.10891
393.194
2.10878
392.926
2.10866
392.662
2.10853
end of experiment